Workbook

Sheet Summary
A1: 25 Woodgreen Place — Executive Summary
A2: Madison, MS • 7-Year Hold • Prepared 5/16/2026
A4: DEAL OVERVIEW | D4: FINANCING (SELECTED)
A5: Purchase price | B5: =Assumptions!$B$5 -> 2650000 | D5: Option selected | E5: =Assumptions!B21&" — "&Assumptions!B22 -> B — Fixed
A6: CapEx (3rd floor build-out) | B6: =Assumptions!$B$6 -> 350000 | D6: Loan amount | E6: =Assumptions!$B$23 -> 2120000
A7: Closing + origination | B7: =Assumptions!$B$7+Assumptions!$B$8 -> 30038.739 | D7: Rate | E7: =Assumptions!$B$24 -> 0.0625
A8: Total project cost | B8: =Assumptions!$B$9 -> 3030038.7 | D8: Monthly P&I | E8: =Assumptions!$B$25 -> 15495.678
D9: Annual debt service | E9: =Assumptions!$B$26 -> 185948.13
D10: Equity required at close | E10: =Assumptions!$B$27 -> 910038.74
A12: RETURNS — 7-YEAR HOLD
A13: Pre-tax IRR (levered) | B13: =Returns!B33 -> 0.12529998 | D13: Min DSCR (hold) | E13: =Returns!B36 -> 0.95721315
A14: After-tax IRR (levered) | B14: =Returns!B34 -> 0.10466671 | D14: Avg DSCR (stabilized) | E14: =Returns!B37 -> 1.4260832
A15: Equity multiple (pre-tax) | B15: =Returns!B31 -> 2.1070478 | D15: Year 7 NOI | E15: =Returns!B4 -> 278926.35
A16: Equity multiple (after-tax) | B16: =Returns!B32 -> 1.7598115 | D16: Year 7 sale price (gross) | E16: =Returns!B6 -> 3281486.5
A17: Avg Cash-on-Cash (Yr 3–7, stabilized) | B17: =Returns!B35 -> 0.087061539 | D17: Year 1 bonus depreciation | E17: =Depreciation!B19 -> 549416.67
A19: REVENUE & NOI BY YEAR
A20: Year | B20: Year 1 | C20: Year 2 | D20: Year 3 | E20: Year 4 | F20: Year 5 | G20: Year 6 | H20: Year 7
A21: Gross Revenue | B21: =Revenue!B7 -> 258000 | C21: =Revenue!C7 -> 287360 | D21: =Revenue!D7 -> 355240 | E21: =Revenue!E7 -> 364817.2 | F21: =Revenue!F7 -> 374654.72 | G21: =Revenue!G7 -> 384759.68 | H21: =Revenue!H7 -> 395139.43
A22: NOI | B22: =CashFlow!B8 -> 250000 | C22: =CashFlow!C8 -> 177992 | D22: =CashFlow!D8 -> 251778 | E22: =CashFlow!E8 -> 258305.34 | F22: =CashFlow!F8 -> 265002.85 | G22: =CashFlow!G8 -> 271874.99 | H22: =CashFlow!H8 -> 278926.35
A23: Pre-tax CF | B23: =CashFlow!B14 -> 64051.865 | C23: =CashFlow!C14 -> -7956.1347 | D23: =CashFlow!D14 -> 65829.865 | E23: =CashFlow!E14 -> 72357.205 | F23: =CashFlow!F14 -> 79054.716 | G23: =CashFlow!G14 -> 85926.86 | H23: =CashFlow!H14 -> 92978.22
A24: After-tax CF | B24: =CashFlow!B23 -> 223284.59 | C24: =CashFlow!C23 -> -6921.4068 | D24: =CashFlow!D23 -> 38170.476 | E24: =CashFlow!E23 -> 40799.783 | F24: =CashFlow!F23 -> 43440.914 | G24: =CashFlow!G23 -> 46090.545 | H24: =CashFlow!H23 -> 48745.033
A25: DSCR | B25: =CashFlow!B25 -> 1.3444609 | C25: =CashFlow!C25 -> 0.95721315 | D25: =CashFlow!D25 -> 1.3540227 | E25: =CashFlow!E25 -> 1.3891257 | F25: =CashFlow!F25 -> 1.4251439 | G25: =CashFlow!G25 -> 1.4621012 | H25: =CashFlow!H25 -> 1.5000223

Sheet Assumptions
A1: 25 Woodgreen Place — Key Assumptions
A2: Madison, MS • 7-Year Analysis • As of 5/16/2026
A4: ACQUISITION
A5: Purchase price | B5: 2650000 | E5: Contract price
A6: CapEx — 3rd floor build-out | B6: 350000 | E6: ~4,000–4,500 SF added on Hood side
A7: Closing costs (appraisal, attorney, environmental) | B7: 30000 | E7: Excluding origination fee
A8: Origination fee (selected option) | B8: =B25*0.0025 -> 38.739195 | E8: 0.25% of selected loan
A9: Total project cost | B9: =B5+B6+B7+B8 -> 3030038.7
A11: FINANCING — RENASANT COMMITMENT (Two Options)
B12: Option A (85%) | C12: Option B (80%)
A13: LTV | B13: 0.85 | C13: 0.8
A14: Loan amount | B14: 2252500 | C14: 2120000 | E14: 85%/80% of $2.65M
A15: Fixed rate (5-yr) | B15: 0.0625 | C15: 0.0625 | E15: Per commitment letter
A16: Floating rate (today) | B16: 0.0584 | C16: 0.0584 | E16: SOFR + 2.25%; cap 6.85%
A17: Amortization (months) | B17: 240 | C17: 240 | E17: 20-year amortization
A18: Term (months) | B18: 60 | C18: 60 | E18: 5-year maturity; refi assumed at maturity
A19: Origination fee (%) | B19: 0.0025 | C19: 0.0025 | E19: 0.25%
A21: Selected option (A or B) | B21: B | E21: Change to "A" to flip to 85% LTV scenario
A22: Rate type (Fixed or Floating) | B22: Fixed | E22: "Fixed" or "Floating"
A23: Selected loan amount | B23: =IF(B21="A",B14,C14) -> 2120000
A24: Selected rate | B24: =IF(B22="Fixed",IF(B21="A",B15,C15),IF(B21="A",B16,C16)) -> 0.0625
A25: Monthly P&I (selected) | B25: =-PMT(B24/12,B17,B23) -> 15495.678
A26: Annual debt service (selected) | B26: =B25*12 -> 185948.13
A27: Equity required at close | B27: =B9-B23 -> 910038.74
A29: REVENUE — HOOD PACKAGING (NNN)
A30: Year 1 Hood rent (consolidated lease) — $/month | B30: 19000 | E30: New 12-mo lease signed at closing
A31: Months 13–18 Hood reduced rent — $/month | B31: 12000 | E31: 6-month construction period
A32: Stabilized Hood NNN rent (mo 19+) — $/month | B32: 18000 | E32: Post-restructure NNN
A33: Annual rent escalator — Hood | B33: 0.025 | E33: Applied starting Year 3
A35: REVENUE — EXECUTIVE SUITES (Gross / Full-Service)
A36: # of executive suites | B36: 16 | E36: Per user
A37: Average monthly rent per suite (stabilized) | B37: 700 | E37: $/mo gross — incl. utilities, internet, reception
A38: Stabilized occupancy | B38: 0.85 | E38: 85% stabilized (industry norm 75–90%)
A39: Months 13–18 occupancy (ramp during construction) | B39: 0.55 | E39: Lease-up while Hood-side construction underway
A40: Year 2 H2 occupancy (mo 19–24) | B40: 0.75 | E40: Continued ramp to stabilization
A41: Annual rent escalator — Exec suites | B41: 0.03 | E41: 3% applied starting Year 4
A43: OPERATING EXPENSES (Landlord-paid; stabilized Year 3)
A44: Property tax — landlord portion (exec side ~34%) | B44: 10500 | E44: Hood reimburses NNN portion (~$20K)
A45: Insurance — landlord portion | B45: 3000 | E45: NNN reimbursement covers Hood share
A46: Utilities (exec suite side) | B46: 18000 | E46: Electric/water/gas — gross to tenants
...

Sheet Debt
A1: Debt Schedule — Both Options
A3: Option A — 85% LTV ($2,252,500) | G3: Option B — 80% LTV ($2,120,000)
A4: Year | B4: Beg Balance | C4: Interest | D4: Principal | E4: End Balance | G4: Year | H4: Beg Balance | I4: Interest | J4: Principal | K4: End Balance
A5: 1 | B5: =Assumptions!$B$14 -> 2252500 | C5: =-CUMIPMT(Assumptions!$B$15/12,Assumptions!$B$17,Assumptions!$B$14,1,12,0) -> 139125.92 | D5: =-CUMPRINC(Assumptions!$B$15/12,Assumptions!$B$17,Assumptions!$B$14,1,12,0) -> 58443.977 | E5: =B5-D5 -> 2194056 | G5: =Assumptions!$C$14 -> 2120000 | H5: =-CUMIPMT(Assumptions!$C$15/12,Assumptions!$B$17,Assumptions!$C$14,1,12,0) -> 130942.04 | I5: =-CUMPRINC(Assumptions!$C$15/12,Assumptions!$B$17,Assumptions!$C$14,1,12,0) -> 55006.096 | J5: =G5-I5 -> 2064993.9
A6: 2 | B6: =E5 -> 2194056 | C6: =-CUMIPMT(Assumptions!$B$15/12,Assumptions!$B$17,Assumptions!$B$14,13,24,0) -> 135366.69 | D6: =-CUMPRINC(Assumptions!$B$15/12,Assumptions!$B$17,Assumptions!$B$14,13,24,0) -> 62203.2 | E6: =B6-D6 -> 2131852.8 | G6: =K5 -> 0 | H6: =-CUMIPMT(Assumptions!$C$15/12,Assumptions!$B$17,Assumptions!$C$14,13,24,0) -> 127403.95 | I6: =-CUMPRINC(Assumptions!$C$15/12,Assumptions!$B$17,Assumptions!$C$14,13,24,0) -> 58544.188 | J6: =G6-I6 -> -58544.188
A7: 3 | B7: =E6 -> 2131852.8 | C7: =-CUMIPMT(Assumptions!$B$15/12,Assumptions!$B$17,Assumptions!$B$14,25,36,0) -> 131365.67 | D7: =-CUMPRINC(Assumptions!$B$15/12,Assumptions!$B$17,Assumptions!$B$14,25,36,0) -> 66204.223 | E7: =B7-D7 -> 2065648.6 | G7: =K6 -> 0 | H7: =-CUMIPMT(Assumptions!$C$15/12,Assumptions!$B$17,Assumptions!$C$14,25,36,0) -> 123638.28 | I7: =-CUMPRINC(Assumptions!$C$15/12,Assumptions!$B$17,Assumptions!$C$14,25,36,0) -> 62309.856 | J7: =G7-I7 -> -62309.856
A8: 4 | B8: =E7 -> 2065648.6 | C8: =-CUMIPMT(Assumptions!$B$15/12,Assumptions!$B$17,Assumptions!$B$14,37,48,0) -> 127107.29 | D8: =-CUMPRINC(Assumptions!$B$15/12,Assumptions!$B$17,Assumptions!$B$14,37,48,0) -> 70462.598 | E8: =B8-D8 -> 1995186 | G8: =K7 -> 0 | H8: =-CUMIPMT(Assumptions!$C$15/12,Assumptions!$B$17,Assumptions!$C$14,37,48,0) -> 119630.4 | I8: =-CUMPRINC(Assumptions!$C$15/12,Assumptions!$B$17,Assumptions!$C$14,37,48,0) -> 66317.74 | J8: =G8-I8 -> -66317.74
A9: 5 | B9: =E8 -> 1995186 | C9: =-CUMIPMT(Assumptions!$B$15/12,Assumptions!$B$17,Assumptions!$B$14,49,60,0) -> 122575.01 | D9: =-CUMPRINC(Assumptions!$B$15/12,Assumptions!$B$17,Assumptions!$B$14,49,60,0) -> 74994.88 | E9: =B9-D9 -> 1920191.1 | G9: =K8 -> 0 | H9: =-CUMIPMT(Assumptions!$C$15/12,Assumptions!$B$17,Assumptions!$C$14,49,60,0) -> 115364.72 | I9: =-CUMPRINC(Assumptions!$C$15/12,Assumptions!$B$17,Assumptions!$C$14,49,60,0) -> 70583.417 | J9: =G9-I9 -> -70583.417
A10: 6 | B10: =E9 -> 1920191.1 | C10: =-CUMIPMT(Assumptions!$B$15/12,Assumptions!$B$17,Assumptions!$B$14,61,72,0) -> 117751.21 | D10: =-CUMPRINC(Assumptions!$B$15/12,Assumptions!$B$17,Assumptions!$B$14,61,72,0) -> 79818.687 | E10: =B10-D10 -> 1840372.4 | G10: =K9 -> 0 | H10: =-CUMIPMT(Assumptions!$C$15/12,Assumptions!$B$17,Assumptions!$C$14,61,72,0) -> 110824.66 | I10: =-CUMPRINC(Assumptions!$C$15/12,Assumptions!$B$17,Assumptions!$C$14,61,72,0) -> 75123.47 | J10: =G10-I10 -> -75123.47
A11: 7 | B11: =E10 -> 1840372.4 | C11: =-CUMIPMT(Assumptions!$B$15/12,Assumptions!$B$17,Assumptions!$B$14,73,84,0) -> 112617.12 | D11: =-CUMPRINC(Assumptions!$B$15/12,Assumptions!$B$17,Assumptions!$B$14,73,84,0) -> 84952.77 | E11: =B11-D11 -> 1755419.7 | G11: =K10 -> 0 | H11: =-CUMIPMT(Assumptions!$C$15/12,Assumptions!$B$17,Assumptions!$C$14,73,84,0) -> 105992.59 | I11: =-CUMPRINC(Assumptions!$C$15/12,Assumptions!$B$17,Assumptions!$C$14,73,84,0) -> 79955.548 | J11: =G11-I11 -> -79955.548
A13: Note: Loan matures at month 60. Model assumes refinance at same rate / fresh terms; principal/interest reflect continued 20-yr amortization.
A15: Selected Loan — Annual Debt Service
A16: Year | B16: Beg Balance | C16: Interest | D16: Principal | E16: Total DS | F16: End Balance
A17: 1 | B17: =Assumptions!$B$23 -> 2120000 | C17: =-CUMIPMT(Assumptions!$B$24/12,Assumptions!$B$17,Assumptions!$B$23,1,12,0) -> 130942.04 | D17: =-CUMPRINC(Assumptions!$B$24/12,Assumptions!$B$17,Assumptions!$B$23,1,12,0) -> 55006.096 | E17: =C17+D17 -> 185948.13 | F17: =B17-D17 -> 2064993.9
A18: 2 | B18: =F17 -> 2064993.9 | C18: =-CUMIPMT(Assumptions!$B$24/12,Assumptions!$B$17,Assumptions!$B$23,13,24,0) -> 127403.95 | D18: =-CUMPRINC(Assumptions!$B$24/12,Assumptions!$B$17,Assumptions!$B$23,13,24,0) -> 58544.188 | E18: =C18+D18 -> 185948.13 | F18: =B18-D18 -> 2006449.7
A19: 3 | B19: =F18 -> 2006449.7 | C19: =-CUMIPMT(Assumptions!$B$24/12,Assumptions!$B$17,Assumptions!$B$23,25,36,0) -> 123638.28 | D19: =-CUMPRINC(Assumptions!$B$24/12,Assumptions!$B$17,Assumptions!$B$23,25,36,0) -> 62309.856 | E19: =C19+D19 -> 185948.13 | F19: =B19-D19 -> 1944139.9
A20: 4 | B20: =F19 -> 1944139.9 | C20: =-CUMIPMT(Assumptions!$B$24/12,Assumptions!$B$17,Assumptions!$B$23,37,48,0) -> 119630.4 | D20: =-CUMPRINC(Assumptions!$B$24/12,Assumptions!$B$17,Assumptions!$B$23,37,48,0) -> 66317.74 | E20: =C20+D20 -> 185948.13 | F20: =B20-D20 -> 1877822.1
A21: 5 | B21: =F20 -> 1877822.1 | C21: =-CUMIPMT(Assumptions!$B$24/12,Assumptions!$B$17,Assumptions!$B$23,49,60,0) -> 115364.72 | D21: =-CUMPRINC(Assumptions!$B$24/12,Assumptions!$B$17,Assumptions!$B$23,49,60,0) -> 70583.417 | E21: =C21+D21 -> 185948.13 | F21: =B21-D21 -> 1807238.7
A22: 6 | B22: =F21 -> 1807238.7 | C22: =-CUMIPMT(Assumptions!$B$24/12,Assumptions!$B$17,Assumptions!$B$23,61,72,0) -> 110824.66 | D22: =-CUMPRINC(Assumptions!$B$24/12,Assumptions!$B$17,Assumptions!$B$23,61,72,0) -> 75123.47 | E22: =C22+D22 -> 185948.13 | F22: =B22-D22 -> 1732115.2
A23: 7 | B23: =F22 -> 1732115.2 | C23: =-CUMIPMT(Assumptions!$B$24/12,Assumptions!$B$17,Assumptions!$B$23,73,84,0) -> 105992.59 | D23: =-CUMPRINC(Assumptions!$B$24/12,Assumptions!$B$17,Assumptions!$B$23,73,84,0) -> 79955.548 | E23: =C23+D23 -> 185948.13 | F23: =B23-D23 -> 1652159.7

Sheet Revenue
A1: Revenue Schedule — 7-Year
B3: Year 1 | C3: Year 2 | D3: Year 3 | E3: Year 4 | F3: Year 5 | G3: Year 6 | H3: Year 7
A4: Hood Packaging rent | B4: =Assumptions!$B$30*12 -> 228000 | C4: =Assumptions!$B$31*6+Assumptions!$B$32*6 -> 180000 | D4: =Assumptions!$B$32*12 -> 216000 | E4: =Assumptions!$B$32*12*(1+Assumptions!$B$33)^(4-3) -> 221400 | F4: =Assumptions!$B$32*12*(1+Assumptions!$B$33)^(5-3) -> 226935 | G4: =Assumptions!$B$32*12*(1+Assumptions!$B$33)^(6-3) -> 232608.38 | H4: =Assumptions!$B$32*12*(1+Assumptions!$B$33)^(7-3) -> 238423.58
A5: Executive suites revenue | B5: 0 | C5: =Assumptions!$B$36*Assumptions!$B$37*(Assumptions!$B$39*6+Assumptions!$B$40*6) -> 87360 | D5: =Assumptions!$B$36*Assumptions!$B$37*Assumptions!$B$38*12 -> 114240 | E5: =Assumptions!$B$36*Assumptions!$B$37*Assumptions!$B$38*12*(1+Assumptions!$B$41)^(4-3) -> 117667.2 | F5: =Assumptions!$B$36*Assumptions!$B$37*Assumptions!$B$38*12*(1+Assumptions!$B$41)^(5-3) -> 121197.22 | G5: =Assumptions!$B$36*Assumptions!$B$37*Assumptions!$B$38*12*(1+Assumptions!$B$41)^(6-3) -> 124833.13 | H5: =Assumptions!$B$36*Assumptions!$B$37*Assumptions!$B$38*12*(1+Assumptions!$B$41)^(7-3) -> 128578.13
A6: NNN reimbursements (Hood pass-throughs) | B6: 30000 | C6: 20000 | D6: 25000 | E6: =D6*(1+Assumptions!$B$57) -> 25750 | F6: =E6*(1+Assumptions!$B$57) -> 26522.5 | G6: =F6*(1+Assumptions!$B$57) -> 27318.175 | H6: =G6*(1+Assumptions!$B$57) -> 28137.72
A7: Total Gross Revenue | B7: =SUM(B4:B6) -> 258000 | C7: =SUM(C4:C6) -> 287360 | D7: =SUM(D4:D6) -> 355240 | E7: =SUM(E4:E6) -> 364817.2 | F7: =SUM(F4:F6) -> 374654.72 | G7: =SUM(G4:G6) -> 384759.68 | H7: =SUM(H4:H6) -> 395139.43
A9: Year 1: Hood single-tenant lease at $19K/mo (current consolidated lease — assumed NNN). Exec suite side not yet operational.
A10: Year 2: Mo 13–18 — Hood at $12K/mo during 3rd-floor construction; exec suites ramping at 55% occ. Mo 19–24 — Hood at $18K NNN; exec suites at 75% occ.
A11: Years 3–7: Stabilized. Hood at $18K/mo NNN with 2.5% escalator. Exec suites at 85% occupancy with 3% escalator.

Sheet OpEx
A1: Operating Expenses — Landlord Paid
B3: Year 1 | C3: Year 2 | D3: Year 3 | E3: Year 4 | F3: Year 5 | G3: Year 6 | H3: Year 7
A4: Year 1: Single-tenant NNN (Hood)
A5: Landlord-paid OpEx (reserves, oversight) | B5: =Assumptions!$B$54 -> 8000
A7: Year 2: Construction + ramp
A8: Months 13–18 LL OpEx (construction half) | C8: =Assumptions!$B$55 -> 45000
A9: Months 19–24 LL OpEx (ramp half) | C9: =Assumptions!$B$56 -> 50000
A11: Years 3–7: Stabilized (annual)
A12: Property tax (LL portion) | D12: =Assumptions!$B$44 -> 10500 | E12: =D12*(1+Assumptions!$B$57) -> 10815 | F12: =E12*(1+Assumptions!$B$57) -> 11139.45 | G12: =F12*(1+Assumptions!$B$57) -> 11473.633 | H12: =G12*(1+Assumptions!$B$57) -> 11817.843
A13: Insurance (LL portion) | D13: =Assumptions!$B$45 -> 3000 | E13: =D13*(1+Assumptions!$B$57) -> 3090 | F13: =E13*(1+Assumptions!$B$57) -> 3182.7 | G13: =F13*(1+Assumptions!$B$57) -> 3278.181 | H13: =G13*(1+Assumptions!$B$57) -> 3376.5264
A14: Utilities (exec side) | D14: =Assumptions!$B$46 -> 18000 | E14: =D14*(1+Assumptions!$B$57) -> 18540 | F14: =E14*(1+Assumptions!$B$57) -> 19096.2 | G14: =F14*(1+Assumptions!$B$57) -> 19669.086 | H14: =G14*(1+Assumptions!$B$57) -> 20259.159
A15: Internet / IT | D15: =Assumptions!$B$47 -> 7200 | E15: =D15*(1+Assumptions!$B$57) -> 7416 | F15: =E15*(1+Assumptions!$B$57) -> 7638.48 | G15: =F15*(1+Assumptions!$B$57) -> 7867.6344 | H15: =G15*(1+Assumptions!$B$57) -> 8103.6634
A16: Reception / admin | D16: =Assumptions!$B$48 -> 20000 | E16: =D16*(1+Assumptions!$B$57) -> 20600 | F16: =E16*(1+Assumptions!$B$57) -> 21218 | G16: =F16*(1+Assumptions!$B$57) -> 21854.54 | H16: =G16*(1+Assumptions!$B$57) -> 22510.176
A17: Cleaning / janitorial | D17: =Assumptions!$B$49 -> 12000 | E17: =D17*(1+Assumptions!$B$57) -> 12360 | F17: =E17*(1+Assumptions!$B$57) -> 12730.8 | G17: =F17*(1+Assumptions!$B$57) -> 13112.724 | H17: =G17*(1+Assumptions!$B$57) -> 13506.106
A18: Marketing / leasing | D18: =Assumptions!$B$50 -> 5000 | E18: =D18*(1+Assumptions!$B$57) -> 5150 | F18: =E18*(1+Assumptions!$B$57) -> 5304.5 | G18: =F18*(1+Assumptions!$B$57) -> 5463.635 | H18: =G18*(1+Assumptions!$B$57) -> 5627.5441
A19: Repairs / maintenance | D19: =Assumptions!$B$51 -> 6000 | E19: =D19*(1+Assumptions!$B$57) -> 6180 | F19: =E19*(1+Assumptions!$B$57) -> 6365.4 | G19: =F19*(1+Assumptions!$B$57) -> 6556.362 | H19: =G19*(1+Assumptions!$B$57) -> 6753.0529
A20: Misc / supplies | D20: =Assumptions!$B$52 -> 4000 | E20: =D20*(1+Assumptions!$B$57) -> 4120 | F20: =E20*(1+Assumptions!$B$57) -> 4243.6 | G20: =F20*(1+Assumptions!$B$57) -> 4370.908 | H20: =G20*(1+Assumptions!$B$57) -> 4502.0352
A21: Property management fee (5% of EGI) | B21: 0 | C21: =Assumptions!$B$53*Revenue!C7 -> 14368 | D21: =Assumptions!$B$53*Revenue!D7 -> 17762 | E21: =Assumptions!$B$53*Revenue!E7 -> 18240.86 | F21: =Assumptions!$B$53*Revenue!F7 -> 18732.736 | G21: =Assumptions!$B$53*Revenue!G7 -> 19237.984 | H21: =Assumptions!$B$53*Revenue!H7 -> 19756.972
A23: Total Operating Expenses | B23: =B5+B21 -> 8000 | C23: =C8+C9+C21 -> 109368 | D23: =SUM(D12:D20)+D21 -> 103462 | E23: =SUM(E12:E20)+E21 -> 106511.86 | F23: =SUM(F12:F20)+F21 -> 109651.87 | G23: =SUM(G12:G20)+G21 -> 112884.69 | H23: =SUM(H12:H20)+H21 -> 116213.08

Sheet Depreciation
A1: Depreciation — Cost Segregation + 100% Bonus
A3: Basis Allocation
A4: Purchase price | B4: =Assumptions!$B$5 -> 2650000
A5: Less: land allocation | B5: =-Assumptions!$B$5*Assumptions!$B$60 -> -397500
A6: Plus: CapEx (3rd floor build-out) | B6: =Assumptions!$B$6 -> 350000
A7: Depreciable basis | B7: =SUM(B4:B6) -> 2602500
A9: 5-yr personal property basis | B9: =B7*Assumptions!$B$61 -> 312300
A10: 15-yr land improvements basis | B10: =B7*Assumptions!$B$62 -> 208200
A11: 39-yr building structure basis | B11: =B7*Assumptions!$B$63 -> 2082000
A14: Annual Depreciation Schedule
B15: Year 1 | C15: Year 2 | D15: Year 3 | E15: Year 4 | F15: Year 5 | G15: Year 6 | H15: Year 7
A16: 5-yr property (100% bonus Y1) | B16: =B9*Assumptions!$B$64 -> 312300 | C16: 0 | D16: 0 | E16: 0 | F16: 0 | G16: 0 | H16: 0
A17: 15-yr property (100% bonus Y1) | B17: =B10*Assumptions!$B$64 -> 208200 | C17: 0 | D17: 0 | E17: 0 | F17: 0 | G17: 0 | H17: 0
A18: 39-yr building (SL, ~½-yr Y1) | B18: =B11/39*(6.5/12) -> 28916.667 | C18: =B11/39 -> 53384.615 | D18: =B11/39 -> 53384.615 | E18: =B11/39 -> 53384.615 | F18: =B11/39 -> 53384.615 | G18: =B11/39 -> 53384.615 | H18: =B11/39 -> 53384.615
A19: Total annual depreciation | B19: =SUM(B16:B18) -> 549416.67 | C19: =SUM(C16:C18) -> 53384.615 | D19: =SUM(D16:D18) -> 53384.615 | E19: =SUM(E16:E18) -> 53384.615 | F19: =SUM(F16:F18) -> 53384.615 | G19: =SUM(G16:G18) -> 53384.615 | H19: =SUM(H16:H18) -> 53384.615
A20: Cumulative depreciation | B20: =B19 -> 549416.67 | C20: =B20+C19 -> 602801.28 | D20: =C20+D19 -> 656185.9 | E20: =D20+E19 -> 709570.51 | F20: =E20+F19 -> 762955.13 | G20: =F20+G19 -> 816339.74 | H20: =G20+H19 -> 869724.36
A22: Bonus depreciation: 100% under One Big Beautiful Bill Act (OBBBA) for property placed in service after 1/19/2025. Provides massive Year 1 deduction. 5-yr and 15-yr classes are bonus-eligible; 39-yr structural is not.

Sheet CashFlow
A1: P&L, Cash Flow, and After-Tax Returns — 7-Year
B3: Year 1 | C3: Year 2 | D3: Year 3 | E3: Year 4 | F3: Year 5 | G3: Year 6 | H3: Year 7
A4: Gross Revenue (from Revenue tab) | B4: =Revenue!B7 -> 258000 | C4: =Revenue!C7 -> 287360 | D4: =Revenue!D7 -> 355240 | E4: =Revenue!E7 -> 364817.2 | F4: =Revenue!F7 -> 374654.72 | G4: =Revenue!G7 -> 384759.68 | H4: =Revenue!H7 -> 395139.43
A5: Less: vacancy reserve (additional) | B5: 0 | C5: 0 | D5: 0 | E5: 0 | F5: 0 | G5: 0 | H5: 0
A6: Effective Gross Income (EGI) | B6: =B4-B5 -> 258000 | C6: =C4-C5 -> 287360 | D6: =D4-D5 -> 355240 | E6: =E4-E5 -> 364817.2 | F6: =F4-F5 -> 374654.72 | G6: =G4-G5 -> 384759.68 | H6: =H4-H5 -> 395139.43
A7: Less: Operating Expenses | B7: =-OpEx!B23 -> -8000 | C7: =-OpEx!C23 -> -109368 | D7: =-OpEx!D23 -> -103462 | E7: =-OpEx!E23 -> -106511.86 | F7: =-OpEx!F23 -> -109651.87 | G7: =-OpEx!G23 -> -112884.69 | H7: =-OpEx!H23 -> -116213.08
A8: Net Operating Income (NOI) | B8: =B6+B7 -> 250000 | C8: =C6+C7 -> 177992 | D8: =D6+D7 -> 251778 | E8: =E6+E7 -> 258305.34 | F8: =F6+F7 -> 265002.85 | G8: =G6+G7 -> 271874.99 | H8: =H6+H7 -> 278926.35
A10: Less: Debt service (interest + principal) | B10: =-Debt!E17 -> -185948.13 | C10: =-Debt!E18 -> -185948.13 | D10: =-Debt!E19 -> -185948.13 | E10: =-Debt!E20 -> -185948.13 | F10: =-Debt!E21 -> -185948.13 | G10: =-Debt!E22 -> -185948.13 | H10: =-Debt!E23 -> -185948.13
A11: memo: Interest portion | B11: =Debt!C17 -> 130942.04 | C11: =Debt!C18 -> 127403.95 | D11: =Debt!C19 -> 123638.28 | E11: =Debt!C20 -> 119630.4 | F11: =Debt!C21 -> 115364.72 | G11: =Debt!C22 -> 110824.66 | H11: =Debt!C23 -> 105992.59
A12: memo: Principal portion | B12: =Debt!D17 -> 55006.096 | C12: =Debt!D18 -> 58544.188 | D12: =Debt!D19 -> 62309.856 | E12: =Debt!D20 -> 66317.74 | F12: =Debt!D21 -> 70583.417 | G12: =Debt!D22 -> 75123.47 | H12: =Debt!D23 -> 79955.548
A14: Pre-tax Cash Flow (NOI − DS) | B14: =B8+B10 -> 64051.865 | C14: =C8+C10 -> -7956.1347 | D14: =D8+D10 -> 65829.865 | E14: =E8+E10 -> 72357.205 | F14: =F8+F10 -> 79054.716 | G14: =G8+G10 -> 85926.86 | H14: =H8+H10 -> 92978.22
A16: TAX CALCULATION (Accelerated Depreciation)
A17: NOI | B17: =B8 -> 250000 | C17: =C8 -> 177992 | D17: =D8 -> 251778 | E17: =E8 -> 258305.34 | F17: =F8 -> 265002.85 | G17: =G8 -> 271874.99 | H17: =H8 -> 278926.35
A18: Less: Interest expense (deductible) | B18: =-B11 -> -130942.04 | C18: =-C11 -> -127403.95 | D18: =-D11 -> -123638.28 | E18: =-E11 -> -119630.4 | F18: =-F11 -> -115364.72 | G18: =-G11 -> -110824.66 | H18: =-H11 -> -105992.59
A19: Less: Depreciation | B19: =-Depreciation!B19 -> -549416.67 | C19: =-Depreciation!C19 -> -53384.615 | D19: =-Depreciation!D19 -> -53384.615 | E19: =-Depreciation!E19 -> -53384.615 | F19: =-Depreciation!F19 -> -53384.615 | G19: =-Depreciation!G19 -> -53384.615 | H19: =-Depreciation!H19 -> -53384.615
A20: Taxable income / (loss) | B20: =B17+B18+B19 -> -430358.71 | C20: =C17+C18+C19 -> -2796.562 | D20: =D17+D18+D19 -> 74755.106 | E20: =E17+E18+E19 -> 85290.329 | F20: =F17+F18+F19 -> 96253.517 | G20: =G17+G18+G19 -> 107665.71 | H20: =H17+H18+H19 -> 119549.15
A21: Income tax (benefit) at ordinary rate | B21: =IF(Assumptions!$B$70="Yes",B20*Assumptions!$B$67,IF(B20<0,0,B20*Assumptions!$B$67)) -> -159232.72 | C21: =IF(Assumptions!$B$70="Yes",C20*Assumptions!$B$67,IF(C20<0,0,C20*Assumptions!$B$67)) -> -1034.7279 | D21: =IF(Assumptions!$B$70="Yes",D20*Assumptions!$B$67,IF(D20<0,0,D20*Assumptions!$B$67)) -> 27659.389 | E21: =IF(Assumptions!$B$70="Yes",E20*Assumptions!$B$67,IF(E20<0,0,E20*Assumptions!$B$67)) -> 31557.422 | F21: =IF(Assumptions!$B$70="Yes",F20*Assumptions!$B$67,IF(F20<0,0,F20*Assumptions!$B$67)) -> 35613.801 | G21: =IF(Assumptions!$B$70="Yes",G20*Assumptions!$B$67,IF(G20<0,0,G20*Assumptions!$B$67)) -> 39836.314 | H21: =IF(Assumptions!$B$70="Yes",H20*Assumptions!$B$67,IF(H20<0,0,H20*Assumptions!$B$67)) -> 44233.187
A23: After-tax Cash Flow | B23: =B14-B21 -> 223284.59 | C23: =C14-C21 -> -6921.4068 | D23: =D14-D21 -> 38170.476 | E23: =E14-E21 -> 40799.783 | F23: =F14-F21 -> 43440.914 | G23: =G14-G21 -> 46090.545 | H23: =H14-H21 -> 48745.033
A25: DSCR (NOI ÷ Debt Service) | B25: =B8/Debt!E17 -> 1.3444609 | C25: =C8/Debt!E18 -> 0.95721315 | D25: =D8/Debt!E19 -> 1.3540227 | E25: =E8/Debt!E20 -> 1.3891257 | F25: =F8/Debt!E21 -> 1.4251439 | G25: =G8/Debt!E22 -> 1.4621012 | H25: =H8/Debt!E23 -> 1.5000223
A26: Cash-on-Cash Return (pre-tax) | B26: =B14/Assumptions!$B$27 -> 0.070383669 | C26: =C14/Assumptions!$B$27 -> -0.008742633 | D26: =D14/Assumptions!$B$27 -> 0.072337432 | E26: =E14/Assumptions!$B$27 -> 0.079510028 | F26: =F14/Assumptions!$B$27 -> 0.086869616 | G26: =G14/Assumptions!$B$27 -> 0.094421101 | H26: =H14/Assumptions!$B$27 -> 0.10216952

Sheet Returns
A1: Returns Summary — IRR & Exit
A3: YEAR 7 EXIT
A4: Year 7 NOI | B4: =CashFlow!H8 -> 278926.35
A5: Exit cap rate | B5: =Assumptions!$B$71 -> 0.085
A6: Gross sale price (NOI / cap rate) | B6: =B4/B5 -> 3281486.5
A7: Less: sale costs | B7: =-B6*Assumptions!$B$72 -> -164074.33
A8: Net sale proceeds | B8: =B6+B7 -> 3117412.2
A9: Less: loan payoff (Year 7 ending balance) | B9: =-Debt!F23 -> -1652159.7
A10: Pre-tax sale equity | B10: =B8+B9 -> 1465252.5
A12: SALE TAX CALC
A13: Adjusted basis (Total project cost − accumulated depr) | B13: =Assumptions!$B$9-Depreciation!H20 -> 2160314.4
A14: Total gain on sale (Net sale − Adj. basis) | B14: =B8-B13 -> 957097.82
A15: Accumulated depreciation (Year 7) | B15: =Depreciation!H20 -> 869724.36
A16: §1245 recapture (5-yr + 15-yr accum depr) | B16: =MIN(B14,Depreciation!B9+Depreciation!B10) -> 520500
A17: §1250 unrecaptured gain (39-yr SL depr) | B17: =MAX(0,MIN(B14-B16,SUM(Depreciation!B18:H18))) -> 349224.36
A18: Long-term capital gain (remainder) | B18: =MAX(0,B14-B16-B17) -> 87373.458
A19: Tax on sale | B19: =B16*Assumptions!$B$67+B17*Assumptions!$B$69+B18*Assumptions!$B$68 -> 297365.78
A20: After-tax sale equity | B20: =B10-B19 -> 1167886.7
A22: CASH FLOW STREAM (for IRR)
A23: Year | B23: 0 | C23: 1 | D23: 2 | E23: 3 | F23: 4 | G23: 5 | H23: 6 | I23: 7
A24: Pre-tax equity CF | B24: =-Assumptions!$B$27 -> -910038.74 | C24: =CashFlow!B14 -> 64051.865 | D24: =CashFlow!C14 -> -7956.1347 | E24: =CashFlow!D14 -> 65829.865 | F24: =CashFlow!E14 -> 72357.205 | G24: =CashFlow!F14 -> 79054.716 | H24: =CashFlow!G14 -> 85926.86 | I24: =CashFlow!H14+B10 -> 1558230.7
A25: After-tax equity CF | B25: =-Assumptions!$B$27 -> -910038.74 | C25: =CashFlow!B23 -> 223284.59 | D25: =CashFlow!C23 -> -6921.4068 | E25: =CashFlow!D23 -> 38170.476 | F25: =CashFlow!E23 -> 40799.783 | G25: =CashFlow!F23 -> 43440.914 | H25: =CashFlow!G23 -> 46090.545 | I25: =CashFlow!H23+B20 -> 1216631.8
A27: KEY RETURN METRICS
A28: Total equity invested | B28: =Assumptions!$B$27 -> 910038.74
A29: Total pre-tax cash returned (Yr 1–7) | B29: =SUM(C24:I24) -> 1917495.1
A30: Total after-tax cash returned (Yr 1–7) | B30: =SUM(C25:I25) -> 1601496.7
A31: Equity Multiple (pre-tax) | B31: =B29/B28 -> 2.1070478
A32: Equity Multiple (after-tax) | B32: =B30/B28 -> 1.7598115
A33: IRR (pre-tax, levered) | B33: =IRR(B24:I24) -> 0.12529998
A34: IRR (after-tax, levered) | B34: =IRR(B25:I25) -> 0.10466671
A35: Avg Cash-on-Cash (Years 3–7, stabilized) | B35: =AVERAGE(CashFlow!D26:H26) -> 0.087061539
A36: Min DSCR across hold | B36: =MIN(CashFlow!B25:H25) -> 0.95721315
A37: Avg DSCR (stabilized, Years 3–7) | B37: =AVERAGE(CashFlow!D25:H25) -> 1.4260832
